Workbook

Sheet Cómo usar este libro
A1: FUNDAMENTOS CUANTITATIVOS PARA NEGOCIOS CREATIVOS · MODELO DE TU NEGOCIO
A2: Un solo libro para las quince semanas. Cada laboratorio agrega una pestaña, no un archivo.
A4: POR QUÉ TODO VIVE EN EL MISMO ARCHIVO
A5: Porque un modelo no es una colección de ejercicios sueltos: es un negocio descrito con números que se van afinando. Si cada semana fuera un archivo aparte, cada semana empezarías de cero y no habría forma de preguntarle nada al conjunto. Aquí tus supuestos viven en un solo lugar, la pestaña «Tu negocio», y las pestañas de cada laboratorio los leen desde ahí. Cambia un supuesto y todo lo que dependa de él se recalcula solo, en todas las semanas a la vez. Eso es exactamente lo que hace un modelo, y es la razón de que valga la pena cargar un archivo que crece.
A7: CÓMO SE CONECTAN LAS PESTAÑAS
A8: Pestaña | B8: Qué contiene | C8: De dónde lee | D8: Para qué sirve
A9: Tu negocio | B9: Tus supuestos, uno por celda | C9: Lo escribes tú | D9: Es la única pestaña donde escribes supuestos. Todo lo demás los lee de aquí.
A10: S01-Lab | B10: Auditoría de la taquería | C10: No lee de nadie | D10: La hoja que se armó en clase, ya corregida. Se queda como está, es el registro de esa sesión.
A11: S02-Lab | B11: La cadena de «por cada» y las palancas | C11: Lee de «Tu negocio» | D11: El referente arriba, tu negocio abajo. Las celdas en verde oscuro son las que viajan desde la otra pestaña.
A12: Vocabulario | B12: Los términos de cada semana | C12: No lee de nadie | D12: Se consulta, no se llena. Crece una sección por semana.
A14: CÓMO LEER LOS COLORES
A15: VERDE | B15: Celda que tú editas. Cámbiala y todo lo demás se recalcula solo.
A16: AZUL | B16: Dato reportado por la fuente. No lo cambies: es el terreno contra el que te comparas.
A17: GRIS | B17: Celda calculada por una fórmula. No escribas aquí, se sobrescribe la fórmula.
A18: TEXTO VERDE | B18: Celda que se lee de otra pestaña. Su valor no vive aquí: vive en «Tu negocio».
A20: Regla de oro: si una celda es gris o tiene el texto en verde, no escribas encima. Si necesitas otro número, cámbialo en la celda verde de donde sale. Es la diferencia entre fijar un número y calcularlo, que es justo lo que se nos escapó en el laboratorio de la Semana 1.

Sheet Tu negocio
A1: TU NEGOCIO · SUPUESTOS ACUMULADOS
A2: Esta es la única pestaña donde escribes supuestos. Todas las demás los leen de aquí.
A4: 1 · LO QUE DECLARASTE EN S01-Lab
A5: Tu ficha de la Semana 1 describía el negocio con dos números. Se quedan aquí porque son la base contra la que vas a comprobar todo lo que agregues después.
A6: Supuesto | B6: Ejemplo · Café Andante | C6: Tu negocio | D6: Qué está diciendo este número
A7: Precio por unidad | B7: 40 | D7: Cuánto cobras por una sola unidad de lo que vendes.
A8: Unidades vendidas por día | B8: 30 | D8: Cuántas unidades salen en un día. Se cuentan unidades, no clientes.
A10: 2 · LO QUE AGREGAS EN S02-Lab
A11: «Unidades por día» escondía dos supuestos distintos: cuánta gente entra y cuánto se lleva cada quien. Separarlos es lo que te deja mover uno sin mover el otro. Y los días abiertos dejan de ser 30 por inercia.
A12: Supuesto | B12: Ejemplo · Café Andante | C12: Tu negocio | D12: Qué está diciendo este número
A13: Clientes por día | B13: 24 | D13: Cuántas personas distintas compran en un día. Es una tasa: el segundo término es tiempo.
A14: Unidades por cada cliente | B14: 1.25 | D14: Cuánto se lleva en promedio quien ya entró. Es una razón, se escribe 1.25 : 1.
A15: Días abiertos al mes | B15: 26 | D15: Cuántos días al mes vendes de verdad. Si descansas, son menos de 30.
A17: 3 · COMPROBACIÓN CONTRA S01-Lab
A18: Los dos supuestos nuevos, multiplicados, tienen que parecerse a las unidades por día que declaraste en la Semana 1. Si no se parecen, uno de los dos está mal puesto, y decir cuál es parte de tu justificación.
A19: Comprobación | B19: Ejemplo · Café Andante | C19: Tu negocio | D19: Cómo se lee
A20: Unidades por día que salen del tablero | B20: =B13*B14 -> 30 | C20: =C13*C14 -> 0 | D20: clientes por día × unidades por cada cliente
A21: Unidades por día que declaraste en S01-Lab | B21: =B8 -> 30 | C21: =C8 -> 0 | D21: viene del bloque 1 de esta misma pestaña
A22: Diferencia | B22: =B20-B21 -> 0 | C22: =C20-C21 -> 0 | D22: =IF(C21=0,"Todavía no has llenado tus supuestos.",IF(ABS(C22)<=C21*0.15,"Se parecen: los dos supuestos son consistentes con lo que declaraste en la Semana 1.","No se parecen. Revisa cuál de los dos supuestos nuevos está mal puesto y dilo en tu justificación.")) -> Todavía no has llenado tus supuestos.

Sheet S01-Lab
A1: FUNDAMENTOS CUANTITATIVOS PARA NEGOCIOS CREATIVOS · SEMANA 1
A2: Auditoría de un referente
A4: CÓMO LEER LOS COLORES
B5: VERDE · celda que tú editas. Cámbiala y todo lo demás se recalcula solo.
B6: AZUL · dato reportado por la fuente. No lo cambies: es el terreno contra el que te comparas.
B7: GRIS · celda calculada por una fórmula. No escribas aquí, se sobrescribe la fórmula.
A9: 1 · PISO, TU SUPUESTO Y TECHO
A10: El piso es el extremo bajo de ventas que reportan las fuentes ($100,000 al mes) y el techo el extremo alto ($300,000). Ninguno es una predicción: juntos marcan el terreno donde es razonable que caiga tu número. La ganancia se queda fija en 10% en las tres filas.
A11: Escenario | B11: Ventas mensuales | C11: Ganancia (% de las ventas) | D11: Ganancia por cada $100k | E11: Ingreso diario | F11: Ganancia diaria | G11: Diferencia vs tu supuesto | H11: Cómo se lee esa diferencia
A12: Piso | B12: 100000 | C12: 0.1 | D12: =B12*C12 -> 10000 | E12: =B12/30 -> 3333.3333 | F12: =E12*C12 -> 333.33333 | G12: =F12-$F$13 -> -333.33333 | H12: =IF(G12<0,"Este escenario deja MENOS al día que tu supuesto. Estar por arriba de él es buena señal.",IF(G12>0,"Este escenario deja MÁS al día que tu supuesto: tu supuesto se queda corto frente a él.","Igual que tu supuesto.")) -> Este escenario deja MENOS al día que tu supuesto. Estar por arriba de él es buena señal.
A13: Tu supuesto | B13: 200000 | C13: 0.1 | D13: =B13*C13 -> 20000 | E13: =B13/30 -> 6666.6667 | F13: =E13*C13 -> 666.66667 | G13: — | H13: Es la fila contra la que se comparan las otras dos.
A14: Techo | B14: 300000 | C14: 0.1 | D14: =B14*C14 -> 30000 | E14: =B14/30 -> 10000 | F14: =E14*C14 -> 1000 | G14: =F14-$F$13 -> 333.33333 | H14: =IF(G14<0,"Este escenario deja MENOS al día que tu supuesto. Estar por arriba de él es buena señal.",IF(G14>0,"Este escenario deja MÁS al día que tu supuesto: tu supuesto se queda corto frente a él.","Igual que tu supuesto.")) -> Este escenario deja MÁS al día que tu supuesto: tu supuesto se queda corto frente a él.
A15: El 10% es LINEAL: es el mismo porcentaje sin importar cuánto vendas, por eso está igual en las tres filas. Si vendes el doble ganas el doble, ni más ni menos. Fórmulas: ingreso diario = ventas del mes ÷ 30 · ganancia diaria = ingreso diario × 10%
A16: Sobre el signo de la columna F: la resta siempre es «esta fila menos tu supuesto». En el Piso sale NEGATIVO y eso es correcto, no es una pérdida: quiere decir que el piso deja menos al día que tu supuesto, o sea que estás por arriba del piso. En el Techo sale positivo porque el techo deja más que tú. Fíjate que las dos diferencias miden lo mismo, $333.33, porque tu supuesto quedó justo a la mitad.
A18: 2 · COMPARACIÓN DE PALANCAS
A19: Dos caminos para subir tu ganancia diaria, los dos partiendo de tu supuesto. El Camino A sube las ventas y deja la ganancia en 10%. El Camino B hace lo contrario: mismas ventas, mejor ganancia.
A20: Escenario | B20: Ventas mensuales | C20: Ganancia (% de las ventas) | D20: Ganancia por cada $100k | E20: Ingreso diario | F20: Ganancia diaria | G20: Diferencia vs tu supuesto | H20: Cómo se lee esa diferencia
A21: Punto de partida (tu supuesto) | B21: =B13 -> 200000 | C21: =C13 -> 0.1 | D21: =B21*C21 -> 20000 | E21: =B21/30 -> 6666.6667 | F21: =E21*C21 -> 666.66667 | G21: — | H21: Es la fila contra la que se comparan los dos caminos.
A22: Camino A · vender más | B22: 250000 | C22: =C13 -> 0.1 | D22: =B22*C22 -> 25000 | E22: =B22/30 -> 8333.3333 | F22: =E22*C22 -> 833.33333 | G22: =F22-$F$21 -> 166.66667 | H22: Ventas a medio camino entre tu supuesto y el techo reportado. La ganancia no se mueve.
A23: Camino B · ganar mejor | B23: =B13 -> 200000 | C23: 0.15 | D23: =B23*C23 -> 30000 | E23: =B23/30 -> 6666.6667 | F23: =E23*C23 -> 1000 | G23: =F23-$F$21 -> 333.33333 | H23: La ganancia sube de 10% a 15%. Las ventas no se mueven.
A24: Con estos números gana el Camino B. La pregunta que sigue no la resuelve la hoja: ¿qué te cuesta menos en tu negocio, vender una cuarta parte más, o ganar 5 puntos más de cada venta que ya haces?

Sheet S02-Lab
A1: S02-Lab · DE LOS NÚMEROS A LA ESTRATEGIA
A2: Primero el referente (la taquería), después tu negocio. El mismo modelo aplicado dos veces.
A4: 1 · LA CADENA DE «POR CADA» DE LA TAQUERÍA
A5: El ingreso mensual de la taquería no es un número suelto: es una cadena de proporciones encadenadas. Cada eslabón se puede mover por separado, y esa es toda la sesión de hoy.
A6: Supuesto | B6: Valor | C6: Unidad | D6: Qué tipo de proporción es
A7: Clientes por día | B7: 87 | C7: clientes por día | D7: Tasa: el segundo término mide tiempo.
A8: Tacos por cada cliente | B8: 3.5 | C8: tacos por cliente | D8: Razón: se escribe 3.5 : 1 y el 1 casi siempre se omite.
A9: Precio del taco | B9: 22 | C9: pesos por taco | D9: Razón: pesos por cada taco. Se queda fijo hoy para aislar el efecto de la proporción.
A10: Días abiertos al mes | B10: 30 | C10: días por mes | D10: Tasa. Es el único de los cuatro que puedes mover tú.
A12: Resultado | B12: Valor | D12: Cómo se calcula
A13: Tacos por día | D13: clientes por día × tacos por cada cliente
A14: Ingreso por día | D14: tacos por día × precio del taco
A15: Ingreso por mes | D15: ingreso por día × días abiertos al mes
A17: 2 · LAS TRES PALANCAS
A18: Cada camino empuja un eslabón distinto de la cadena, con el movimiento más chico que ese eslabón puede dar en la práctica. No hay medio cliente, y 0.1 tacos por cliente quiere decir que 1 de cada 10 pide uno extra.
A19: Camino | B19: Cuánto suma al mes | D19: De qué depende ese número
A20: Camino A · +1 cliente por día | D20: Un cliente más deja lo que se lleva un cliente, todos los días que abres. No cambia si mueves «clientes por día».
A21: Camino B · +0.1 tacos por cada cliente | D21: Esa décima se cobra en cada cliente que ya entra. No cambia si mueves «tacos por cada cliente».
A22: Camino C · +1 día abierto al mes | D22: Un día más vale lo que vende un día. No cambia si mueves «días abiertos al mes».
A23: El Camino C no compite con los otros dos. El mes tiene entre 28 y 31 días y ahí se acaba: es un recurso que se agota, no una proporción que se pueda seguir empujando. Por eso se mira aparte aunque su número sea el más grande.
A25: 3 · EL PUNTO DE CRUCE
A26: A y B no siempre ganan lo mismo. Hay un número exacto de clientes donde empatan, y de ese número depende cuál de los dos es la métrica que importa hoy.
A27: Clientes por día donde A y B empatan | B27: =10*B8 -> 35 | C27: clientes por día | D27: La regla: clientes = 10 × tacos por cada cliente.
A28: ¿De qué lado está esta taquería? | B28: =IF(B7>B27,"Por arriba del cruce: gana el Camino B. Con esta proporción, esa décima de taco cae sobre cada uno de los clientes que ya tienes.",IF(B7<B27,"Por debajo del cruce: gana el Camino A. Con pocos clientes, traer uno nuevo pesa más que subirle el promedio a los que hay.","Justo en el cruce: los dos caminos empatan.")) -> Por arriba del cruce: gana el Camino B. Con esta proporción, esa décima de taco cae sobre cada uno de los clientes que ya tienes.
A30: 4 · EL TAMAÑO DE CADA EMPUJÓN
A31: Antes de concluir nada, vale medir los dos empujones contra la base sobre la que caen. Son la unidad más chica de cada palanca, pero eso no los vuelve del mismo tamaño entre sí.
A32: Medida | B32: Valor | D32: Cómo se lee
A33: +1 cliente, sobre los clientes que ya hay | B33: =1/B7 -> 0.011494253 | D33: 1 entre 87.
A34: +0.1 tacos, sobre los tacos que ya se llevan | B34: =0.1/B8 -> 0.028571429 | D34: 0.1 entre 3.5.
A35: Cuántas veces más grande es el empujón de B | B35: =(0.1/B8)/(1/B7) -> 2.4857143 | D35: el segundo entre el primero.
A36: Cuántas veces más rinde B que A, en pesos | B36: =IF(B20=0,"Se llena al construir el bloque 2.",B21/B20) -> Se llena al construir el bloque 2. | D36: el Camino B entre el Camino A.
A37: Las dos últimas filas dan el mismo número. Que el Camino B rinda más del doble no es una virtud escondida de la taquería: es el tamaño del empujón. Un mismo movimiento absoluto no pesa igual en las dos palancas, y cuánto rinde depende de la base sobre la que cae. Por eso la métrica que importa cambia según en qué proporción esté parado el negocio.
A39: 5 · ¿Y SI LOS DOS EMPUJONES FUERAN DE LA MISMA PROPORCIÓN?
A40: Cambia la celda verde y observa las dos filas de abajo. Prueba 1%, 5%, 20%.
A41: Tamaño del empujón | B41: 0.05 | D41: La misma fracción se aplica a los dos caminos.
A42: Camino ajustado | B42: Cuánto suma al mes | D42: Qué se movió
A43: Camino A · más clientes, en esa proporción | B43: =B9*(B7*B41)*B8*B10 -> 10048.5 | D43: sube solo «clientes por día».
A44: Camino B · más tacos por cliente, en esa proporción | B44: =B9*B7*(B8*B41)*B10 -> 10048.5 | D44: sube solo «tacos por cada cliente».
A45: Diferencia entre los dos | B45: =B43-B44 -> 0 | D45: sale cero, y sigue saliendo cero con cualquier número que pongas arriba.
A46: No es un error de la hoja. Un empujón de la misma proporción multiplica la misma cadena, sin importar por cuál eslabón entres. Entonces la pregunta que sí decide no es cuál rinde más aquí, sino cuál de los dos empujones es más realista de conseguir en tu negocio.
...

Sheet Comprobación
A1: COMPROBACIÓN · ¿VA BIEN LA HOJA?
A2: Esta pestaña no se llena. Se mira. Dice qué falta por construir y si lo construido da lo que debe dar.
A4: 1 · DE DÓNDE VENIMOS · lo que quedó en S01-Lab
A5: La pestaña S01-Lab es la hoja de la semana pasada ya corregida. No se toca. Estos son sus tres resultados, leídos directamente de ahí: si aparecen, la pestaña está intacta.
A6: Escenario | C6: Ganancia diaria | F6: Cómo se lee
A7: Piso | C7: ='S01-Lab'!F12 -> 333.33333 | F7: El triple de ventas da el triple de ganancia. Eso es que el 10% sea lineal.
A8: Tu supuesto | C8: ='S01-Lab'!F13 -> 666.66667
A9: Techo | C9: ='S01-Lab'!F14 -> 1000
A11: 2 · LO QUE SE CONSTRUYE HOY · trece celdas
A12: «Debe dar» es el resultado correcto de la taquería, que es igual para todos. Las cuatro conexiones y la cadena propia dependen de los números de cada quien, así que ahí solo se revisa que estén puestas.
A13: Bloque | B13: Celda | C13: Qué se escribe ahí | D13: Debe dar | E13: Lo que hay ahora | F13: Estado
A14: 1 · Cadena de la taquería | B14: B13 | C14: =B7*B8 | D14: 304.5 | E14: ='S02-Lab'!B13 -> 0 | F14: =IF(E14=0,"por construir",IF(ABS(E14-D14)<0.01,"OK","revisar la fórmula")) -> por construir
A15: 1 · Cadena de la taquería | B15: B14 | C15: =B13*B9 | D15: 6699 | E15: ='S02-Lab'!B14 -> 0 | F15: =IF(E15=0,"por construir",IF(ABS(E15-D15)<0.01,"OK","revisar la fórmula")) -> por construir
A16: 1 · Cadena de la taquería | B16: B15 | C16: =B14*B10 | D16: 200970 | E16: ='S02-Lab'!B15 -> 0 | F16: =IF(E16=0,"por construir",IF(ABS(E16-D16)<0.01,"OK","revisar la fórmula")) -> por construir
A17: 2 · Las tres palancas | B17: B20 | C17: =B9*B8*B10 | D17: 2310 | E17: ='S02-Lab'!B20 -> 0 | F17: =IF(E17=0,"por construir",IF(ABS(E17-D17)<0.01,"OK","revisar la fórmula")) -> por construir
A18: 2 · Las tres palancas | B18: B21 | C18: =B9*B7*0.1*B10 | D18: 5742 | E18: ='S02-Lab'!B21 -> 0 | F18: =IF(E18=0,"por construir",IF(ABS(E18-D18)<0.01,"OK","revisar la fórmula")) -> por construir
A19: 2 · Las tres palancas | B19: B22 | C19: =B14 | D19: 6699 | E19: ='S02-Lab'!B22 -> 0 | F19: =IF(E19=0,"por construir",IF(ABS(E19-D19)<0.01,"OK","revisar la fórmula")) -> por construir
A20: 6 · Conexión con tu negocio | B20: C51 | C20: ='Tu negocio'!C7 | D20: lo que pusiste en Tu negocio | E20: ='S02-Lab'!C51 -> 0 | F20: =IF('Tu negocio'!C7="","llena primero Tu negocio",IF('S02-Lab'!C51='Tu negocio'!C7,"conectada","falta conectar")) -> llena primero Tu negocio
A21: 6 · Conexión con tu negocio | B21: C52 | C21: ='Tu negocio'!C13 | D21: lo que pusiste en Tu negocio | E21: ='S02-Lab'!C52 -> 0 | F21: =IF('Tu negocio'!C7="","llena primero Tu negocio",IF('S02-Lab'!C52='Tu negocio'!C13,"conectada","falta conectar")) -> llena primero Tu negocio
A22: 6 · Conexión con tu negocio | B22: C53 | C22: ='Tu negocio'!C14 | D22: lo que pusiste en Tu negocio | E22: ='S02-Lab'!C53 -> 0 | F22: =IF('Tu negocio'!C7="","llena primero Tu negocio",IF('S02-Lab'!C53='Tu negocio'!C14,"conectada","falta conectar")) -> llena primero Tu negocio
A23: 6 · Conexión con tu negocio | B23: C54 | C23: ='Tu negocio'!C15 | D23: lo que pusiste en Tu negocio | E23: ='S02-Lab'!C54 -> 0 | F23: =IF('Tu negocio'!C7="","llena primero Tu negocio",IF('S02-Lab'!C54='Tu negocio'!C15,"conectada","falta conectar")) -> llena primero Tu negocio
A24: 6 · Tu propia cadena | B24: C57 | C24: =C52*C53 | D24: depende de tus números | E24: ='S02-Lab'!C57 -> 0 | F24: =IF('Tu negocio'!C7="","llena primero Tu negocio",IF('S02-Lab'!C57>0,"OK","por construir")) -> llena primero Tu negocio
A25: 6 · Tu propia cadena | B25: C58 | C25: =C57*C51 | D25: depende de tus números | E25: ='S02-Lab'!C58 -> 0 | F25: =IF('Tu negocio'!C7="","llena primero Tu negocio",IF('S02-Lab'!C58>0,"OK","por construir")) -> llena primero Tu negocio
A26: 6 · Tu propia cadena | B26: C59 | C26: =C58*C54 | D26: depende de tus números | E26: ='S02-Lab'!C59 -> 0 | F26: =IF('Tu negocio'!C7="","llena primero Tu negocio",IF('S02-Lab'!C59>0,"OK","por construir")) -> llena primero Tu negocio
A27: Avance | C27: =COUNTIF(F14:F26,"OK")+COUNTIF(F14:F26,"conectada")&" de 13 celdas listas" -> 0 de 13 celdas listas | E27: =IF(COUNTIF(F14:F26,"revisar*")+COUNTIF(F14:F26,"falta conectar")>0,"Hay algo que revisar, mira la columna Estado.","Nada marcado para revisar.") -> Nada marcado para revisar.
A29: 3 · CÓMO DEBE QUEDAR · los números de la taquería
A30: Estos seis no dependen del negocio de nadie: son la taquería y salen iguales en todas las máquinas. Si alguno no coincide, la fórmula de esa celda apunta a la fila equivocada.
A31: Qué es | C31: Valor | F31: Cómo comprobarlo a mano
A32: Tacos por día | C32: 304.5 | F32: 87 × 3.5
A33: Ingreso por día | C33: 6699 | F33: 304.5 × 22
A34: Ingreso por mes | C34: 200970 | F34: 6,699 × 30
A35: Camino A · +1 cliente | C35: 2310 | F35: 22 × 3.5 × 30
A36: Camino B · +0.1 tacos | C36: 5742 | F36: 22 × 87 × 0.1 × 30
A37: Camino C · +1 día | C37: 6699 | F37: el ingreso de un día
A38: Punto de cruce | C38: 35 | F38: 10 × 3.5
A39: Cuántas veces rinde más B que A | C39: 2.4857 | F39: 5,742 ÷ 2,310, y también 2.86% ÷ 1.15%
A41: Café Andante, por si alguien quiere comprobar el bloque 6 con el ejemplo: 30 unidades por día, $1,200 al día, $31,200 al mes, Camino A +$1,300, Camino B +$2,496, cruce en 12.5 clientes.

Sheet Vocabulario
A1: VOCABULARIO ACUMULADO
A2: Las definiciones son las mismas del glosario de la app. Se consultan, no se reescriben.
A4: SEMANA 1 · ¿POR QUÉ LOS NÚMEROS?
A5: Término | B5: Definición | C5: Semana | D5: Categoría
A6: Dato | B6: Un valor concreto que se observa o se mide: cuánto cobra un competidor, cuántas personas pasan frente a un local en una hora, cuánto cuesta un insumo. | C6: 1 | D6: general
A7: Métrica | B7: El dato que sí importa seguir de cerca porque de él depende una decisión. No todos los datos son igual de importantes. | C7: 1 | D7: general
A8: Modelo | B8: Una versión simplificada de la realidad de un negocio que se usa para tomar una decisión concreta: cuánto cobrar, cuánta gente necesito, si el negocio se sostiene. | C8: 1 | D8: general
A9: Referente | B9: Un negocio que ya existe y que sirve de comparación. Sus números, aunque no sean exactos para tu caso, dan una primera idea de qué esperar. | C9: 1 | D9: general
A10: Supuesto | B10: Algo que el modelo da por cierto sin haberlo confirmado todavía. Nombrarlo es lo que permite revisar el modelo después, cuando lleguen datos reales. | C10: 1 | D10: general
A11: Piso | B11: El resultado más bajo que es razonable esperar, calculado usando el extremo conservador de lo que reportan negocios parecidos al tuyo. No es la predicción de un desastre ni el peor caso imaginable: es el borde de abajo del terreno donde tiene sentido que caiga tu número. | C11: 1 | D11: general
A12: Techo | B12: El resultado más alto que es razonable esperar, calculado usando el extremo favorable de lo que reportan negocios parecidos al tuyo. Es el borde de arriba del mismo terreno que marca el piso, no una meta ni una promesa. | C12: 1 | D12: general
A14: SEMANA 2 · DE LOS NÚMEROS A LA ESTRATEGIA
A15: Término | B15: Definición | C15: Semana | D15: Categoría
A16: Proporción / razón | B16: La comparación entre dos cantidades que dice qué tanto corresponde de una por cada unidad de la otra: por ejemplo, tacos por cada cliente. | C16: 2 | D16: matematico
A17: Tasa | B17: Una proporción donde el segundo término es tiempo, como clientes por día o ventas por mes. | C17: 2 | D17: matematico
A18: La métrica que importa | B18: La palanca que, con los supuestos actuales del negocio, más mueve el resultado si se mueve ella. No es la única métrica del negocio, es la más sensible en un momento dado. | C18: 2 | D18: negocio
A19: Palanca | B19: Un número del modelo que, al cambiarlo, cambia el resultado; distintas palancas mueven el resultado en distinta medida. | C19: 2 | D19: negocio
A20: Tablero de supuestos | B20: El conjunto de supuestos de un negocio puestos juntos y editables, para poder preguntar qué pasaría si alguno de esos números fuera distinto. | C20: 2 | D20: negocio
